Workbook

Sheet Dashboard
A1: FIELD FORCE & TRADE MARKETING PERFORMANCE DASHBOARD
A2: Market Express | Real sales data (Kaggle Parch & Posey) + simulated field-execution layer
A4: TOTAL SALES | D4: SALES ACHIEVEMENT | G4: VISIT COMPLETION | J4: MERCHANDISING | M4: AVAILABILITY
A6: =SUM(tblGapAnalysis[Total_Actual_Sales]) -> 8574894.9 | D6: =SUM(tblGapAnalysis[Total_Actual_Sales])/SUM(tblGapAnalysis[Total_Target]) -> 0.91920244 | G6: =SUM(tblGapAnalysis[Total_Completed_Visits])/SUM(tblGapAnalysis[Total_Planned_Visits]) -> 0.79386333 | J6: =AVERAGE(tblGapAnalysis[Avg_Merchandising]) -> 0.73519248 | M6: =AVERAGE(tblGapAnalysis[Avg_Availability]) -> 0.76488368
A60: CHART SOURCE DATA (auto-calculated - do not delete)
A62: Region_Summary
A63: Region | B63: Total_Sales | C63: Total_Target | D63: Achievement
A64: Northeast | B64: =SUMIF(tblGapAnalysis[Region],A64,tblGapAnalysis[Total_Actual_Sales]) -> 2968473.8 | C64: =SUMIF(tblGapAnalysis[Region],A64,tblGapAnalysis[Total_Target]) -> 2979022 | D64: =B64/C64 -> 0.99645918
A65: Midwest | B65: =SUMIF(tblGapAnalysis[Region],A65,tblGapAnalysis[Total_Actual_Sales]) -> 1021466.9 | C65: =SUMIF(tblGapAnalysis[Region],A65,tblGapAnalysis[Total_Target]) -> 1305074.8 | D65: =B65/C65 -> 0.78268837
A66: Southeast | B66: =SUMIF(tblGapAnalysis[Region],A66,tblGapAnalysis[Total_Actual_Sales]) -> 2330481.5 | C66: =SUMIF(tblGapAnalysis[Region],A66,tblGapAnalysis[Total_Target]) -> 2391035.3 | D66: =B66/C66 -> 0.97467468
A67: West | B67: =SUMIF(tblGapAnalysis[Region],A67,tblGapAnalysis[Total_Actual_Sales]) -> 2254472.7 | C67: =SUMIF(tblGapAnalysis[Region],A67,tblGapAnalysis[Total_Target]) -> 2653493 | D67: =B67/C67 -> 0.84962453
A70: Monthly_Sales_Trend (all order history)
A71: Year | B71: Month_Num | C71: Label | D71: Total_Sales
A72: 2013 | B72: 12 | C72: =TEXT(DATE(A72,B72,1),"mmm-yy") -> Dec-13 | D72: =SUMIFS(tblCleanOrders[Sales_USD],tblCleanOrders[Year],A72,tblCleanOrders[Month],B72) -> 177253.97
A73: 2014 | B73: 1 | C73: =TEXT(DATE(A73,B73,1),"mmm-yy") -> Jan-14 | D73: =SUMIFS(tblCleanOrders[Sales_USD],tblCleanOrders[Year],A73,tblCleanOrders[Month],B73) -> 122885.95
A74: 2014 | B74: 2 | C74: =TEXT(DATE(A74,B74,1),"mmm-yy") -> Feb-14 | D74: =SUMIFS(tblCleanOrders[Sales_USD],tblCleanOrders[Year],A74,tblCleanOrders[Month],B74) -> 131403.48
A75: 2014 | B75: 3 | C75: =TEXT(DATE(A75,B75,1),"mmm-yy") -> Mar-14 | D75: =SUMIFS(tblCleanOrders[Sales_USD],tblCleanOrders[Year],A75,tblCleanOrders[Month],B75) -> 120550.45
A76: 2014 | B76: 4 | C76: =TEXT(DATE(A76,B76,1),"mmm-yy") -> Apr-14 | D76: =SUMIFS(tblCleanOrders[Sales_USD],tblCleanOrders[Year],A76,tblCleanOrders[Month],B76) -> 129531.54
A77: 2014 | B77: 5 | C77: =TEXT(DATE(A77,B77,1),"mmm-yy") -> May-14 | D77: =SUMIFS(tblCleanOrders[Sales_USD],tblCleanOrders[Year],A77,tblCleanOrders[Month],B77) -> 135189.54
A78: 2014 | B78: 6 | C78: =TEXT(DATE(A78,B78,1),"mmm-yy") -> Jun-14 | D78: =SUMIFS(tblCleanOrders[Sales_USD],tblCleanOrders[Year],A78,tblCleanOrders[Month],B78) -> 141307.68
A79: 2014 | B79: 7 | C79: =TEXT(DATE(A79,B79,1),"mmm-yy") -> Jul-14 | D79: =SUMIFS(tblCleanOrders[Sales_USD],tblCleanOrders[Year],A79,tblCleanOrders[Month],B79) -> 143000.86
A80: 2014 | B80: 8 | C80: =TEXT(DATE(A80,B80,1),"mmm-yy") -> Aug-14 | D80: =SUMIFS(tblCleanOrders[Sales_USD],tblCleanOrders[Year],A80,tblCleanOrders[Month],B80) -> 144575.8
A81: 2014 | B81: 9 | C81: =TEXT(DATE(A81,B81,1),"mmm-yy") -> Sep-14 | D81: =SUMIFS(tblCleanOrders[Sales_USD],tblCleanOrders[Year],A81,tblCleanOrders[Month],B81) -> 138001.5
A82: 2014 | B82: 10 | C82: =TEXT(DATE(A82,B82,1),"mmm-yy") -> Oct-14 | D82: =SUMIFS(tblCleanOrders[Sales_USD],tblCleanOrders[Year],A82,tblCleanOrders[Month],B82) -> 170563.92
A83: 2014 | B83: 11 | C83: =TEXT(DATE(A83,B83,1),"mmm-yy") -> Nov-14 | D83: =SUMIFS(tblCleanOrders[Sales_USD],tblCleanOrders[Year],A83,tblCleanOrders[Month],B83) -> 143850.71
... A109: 2017 | B109: 1 | C109: =TEXT(DATE(A109,B109,1),"mmm-yy") -> Jan-17 | D109: =SUMIFS(tblCleanOrders[Sales_USD],tblCleanOrders[Year],A109,tblCleanOrders[Month],B109) -> 23424.03
A112: Top_10_Reps_by_Sales
A113: Rep_Name | B113: Total_Sales
A114: =Rep_Performance!B2 -> Earlie Schleusner | B114: =Rep_Performance!D2 -> 506470.92
A115: =Rep_Performance!B3 -> Moon Torian | B115: =Rep_Performance!D3 -> 474372.08
A116: =Rep_Performance!B4 -> Vernita Plump | B116: =Rep_Performance!D4 -> 472044.16
A117: =Rep_Performance!B5 -> Tia Amato | B117: =Rep_Performance!D5 -> 466213.64
A118: =Rep_Performance!B6 -> Dawna Agnew | B118: =Rep_Performance!D6 -> 410948.92
A119: =Rep_Performance!B7 -> Maryanna Fiorentino | B119: =Rep_Performance!D7 -> 363890.51
A120: =Rep_Performance!B8 -> Nelle Meaux | B120: =Rep_Performance!D8 -> 359779.88
A121: =Rep_Performance!B9 -> Elwood Shutt | B121: =Rep_Performance!D9 -> 346698.05
A122: =Rep_Performance!B10 -> Delilah Krum | B122: =Rep_Performance!D10 -> 315747.89
A123: =Rep_Performance!B11 -> Charles Bidwell | B123: =Rep_Performance!D11 -> 306753.04
A126: Bottom_10_Reps_by_Achievement
A127: Rep_Name | B127: Sales_Achievement
...

Sheet Final_Report
B1: FINAL REPORT — EXECUTIVE SUMMARY
B2: Field Force & Trade Marketing Performance Dashboard | Market Express | Real sales data (Kaggle Parch & Posey) + simulated field-execution layer
B4: PERFORMANCE SNAPSHOT
B5: TOTAL SALES | C5: SALES ACHIEVEMENT | D5: VISIT COMPLETION | E5: AVG MERCHANDISING | F5: AVG AVAILABILITY
B6: =SUM(tblGapAnalysis[Total_Actual_Sales]) -> 8574894.9 | C6: =SUM(tblGapAnalysis[Total_Actual_Sales])/SUM(tblGapAnalysis[Total_Target]) -> 0.91920244 | D6: =SUM(tblGapAnalysis[Total_Completed_Visits])/SUM(tblGapAnalysis[Total_Planned_Visits]) -> 0.79386333 | E6: =AVERAGE(tblGapAnalysis[Avg_Merchandising]) -> 0.73519248 | F6: =AVERAGE(tblGapAnalysis[Avg_Availability]) -> 0.76488368
B8: REP STATUS MIX
B9: HEALTHY | C9: AT RISK | D9: CRITICAL
B10: =COUNTIF(tblGapAnalysis[Status],"Healthy") -> 16 | C10: =COUNTIF(tblGapAnalysis[Status],"At Risk") -> 9 | D10: =COUNTIF(tblGapAnalysis[Status],"Critical") -> 25 | E10: ="out of "&COUNTA(tblGapAnalysis[Rep_ID])&" reps" -> out of 50 reps
B12: EXECUTIVE SUMMARY
B13: Across 50 sales representatives and 25 months (Jan 2015-Jan 2017), Market Express reached roughly 92% of its combined sales target, but that headline figure hides a wide spread: half the sales force (25 of 50 reps) is flagged At Risk or Critical, and 25 reps are Critical on both commercial and execution metrics at once. Visit completion (79%) is materially weaker than attendance, and average merchandising compliance (74%) and product availability (76%) both sit well below their 90% and 95% targets - the field-execution layer is the more consistent shortfall across the business, not sales alone. The sections below separate reps whose shortfall looks commercial (sales gap, healthy execution) from reps whose shortfall looks operational (sales gap plus weak visits/merchandising/availability), so management can route each case to the right team.
B15: REGIONAL PERFORMANCE
B16: Region | C16: Total Sales | D16: Total Target | E16: Sales Gap | F16: Achievement % | G16: Avg Merchandising
B17: Northeast | C17: =SUMIF(tblGapAnalysis[Region],B17,tblGapAnalysis[Total_Actual_Sales]) -> 2968473.8 | D17: =SUMIF(tblGapAnalysis[Region],B17,tblGapAnalysis[Total_Target]) -> 2979022 | E17: =C17-D17 -> -10548.183 | F17: =C17/D17 -> 0.99645918 | G17: =AVERAGEIF(tblGapAnalysis[Region],B17,tblGapAnalysis[Avg_Merchandising]) -> 0.71291905
B18: Midwest | C18: =SUMIF(tblGapAnalysis[Region],B18,tblGapAnalysis[Total_Actual_Sales]) -> 1021466.9 | D18: =SUMIF(tblGapAnalysis[Region],B18,tblGapAnalysis[Total_Target]) -> 1305074.8 | E18: =C18-D18 -> -283607.94 | F18: =C18/D18 -> 0.78268837 | G18: =AVERAGEIF(tblGapAnalysis[Region],B18,tblGapAnalysis[Avg_Merchandising]) -> 0.74890711
B19: Southeast | C19: =SUMIF(tblGapAnalysis[Region],B19,tblGapAnalysis[Total_Actual_Sales]) -> 2330481.5 | D19: =SUMIF(tblGapAnalysis[Region],B19,tblGapAnalysis[Total_Target]) -> 2391035.3 | E19: =C19-D19 -> -60553.734 | F19: =C19/D19 -> 0.97467468 | G19: =AVERAGEIF(tblGapAnalysis[Region],B19,tblGapAnalysis[Avg_Merchandising]) -> 0.7237572
B20: West | C20: =SUMIF(tblGapAnalysis[Region],B20,tblGapAnalysis[Total_Actual_Sales]) -> 2254472.7 | D20: =SUMIF(tblGapAnalysis[Region],B20,tblGapAnalysis[Total_Target]) -> 2653493 | E20: =C20-D20 -> -399020.25 | F20: =C20/D20 -> 0.84962453 | G20: =AVERAGEIF(tblGapAnalysis[Region],B20,tblGapAnalysis[Avg_Merchandising]) -> 0.7810588
B22: TOP 5 REPS BY SALES GAP (AHEAD OF TARGET)
B23: Rep Name | C23: Region | D23: Sales Gap | E23: Achievement % | F23: Status
B24: =INDEX(tblGapAnalysis[Rep_Name],MATCH(LARGE(tblGapAnalysis[Sales_Gap],1),tblGapAnalysis[Sales_Gap],0)) -> Elwood Shutt | C24: =INDEX(tblGapAnalysis[Region],MATCH(LARGE(tblGapAnalysis[Sales_Gap],1),tblGapAnalysis[Sales_Gap],0)) -> West | D24: =LARGE(tblGapAnalysis[Sales_Gap],1) -> 65367.013 | E24: =INDEX(tblGapAnalysis[Sales_Achievement],MATCH(LARGE(tblGapAnalysis[Sales_Gap],1),tblGapAnalysis[Sales_Gap],0)) -> 1.2539512 | F24: =INDEX(tblGapAnalysis[Status],MATCH(LARGE(tblGapAnalysis[Sales_Gap],1),tblGapAnalysis[Sales_Gap],0)) -> At Risk
B25: =INDEX(tblGapAnalysis[Rep_Name],MATCH(LARGE(tblGapAnalysis[Sales_Gap],2),tblGapAnalysis[Sales_Gap],0)) -> Maryanna Fiorentino | C25: =INDEX(tblGapAnalysis[Region],MATCH(LARGE(tblGapAnalysis[Sales_Gap],2),tblGapAnalysis[Sales_Gap],0)) -> West | D25: =LARGE(tblGapAnalysis[Sales_Gap],2) -> 59823.22 | E25: =INDEX(tblGapAnalysis[Sales_Achievement],MATCH(LARGE(tblGapAnalysis[Sales_Gap],2),tblGapAnalysis[Sales_Gap],0)) -> 1.2266749 | F25: =INDEX(tblGapAnalysis[Status],MATCH(LARGE(tblGapAnalysis[Sales_Gap],2),tblGapAnalysis[Sales_Gap],0)) -> Healthy
B26: =INDEX(tblGapAnalysis[Rep_Name],MATCH(LARGE(tblGapAnalysis[Sales_Gap],3),tblGapAnalysis[Sales_Gap],0)) -> Arica Stoltzfus | C26: =INDEX(tblGapAnalysis[Region],MATCH(LARGE(tblGapAnalysis[Sales_Gap],3),tblGapAnalysis[Sales_Gap],0)) -> West | D26: =LARGE(tblGapAnalysis[Sales_Gap],3) -> 54616.838 | E26: =INDEX(tblGapAnalysis[Sales_Achievement],MATCH(LARGE(tblGapAnalysis[Sales_Gap],3),tblGapAnalysis[Sales_Gap],0)) -> 1.3076714 | F26: =INDEX(tblGapAnalysis[Status],MATCH(LARGE(tblGapAnalysis[Sales_Gap],3),tblGapAnalysis[Sales_Gap],0)) -> At Risk
B27: =INDEX(tblGapAnalysis[Rep_Name],MATCH(LARGE(tblGapAnalysis[Sales_Gap],4),tblGapAnalysis[Sales_Gap],0)) -> Vernita Plump | C27: =INDEX(tblGapAnalysis[Region],MATCH(LARGE(tblGapAnalysis[Sales_Gap],4),tblGapAnalysis[Sales_Gap],0)) -> Southeast | D27: =LARGE(tblGapAnalysis[Sales_Gap],4) -> 49203.456 | E27: =INDEX(tblGapAnalysis[Sales_Achievement],MATCH(LARGE(tblGapAnalysis[Sales_Gap],4),tblGapAnalysis[Sales_Gap],0)) -> 1.1403964 | F27: =INDEX(tblGapAnalysis[Status],MATCH(LARGE(tblGapAnalysis[Sales_Gap],4),tblGapAnalysis[Sales_Gap],0)) -> Healthy
B28: =INDEX(tblGapAnalysis[Rep_Name],MATCH(LARGE(tblGapAnalysis[Sales_Gap],5),tblGapAnalysis[Sales_Gap],0)) -> Necole Victory | C28: =INDEX(tblGapAnalysis[Region],MATCH(LARGE(tblGapAnalysis[Sales_Gap],5),tblGapAnalysis[Sales_Gap],0)) -> Northeast | D28: =LARGE(tblGapAnalysis[Sales_Gap],5) -> 39607.853 | E28: =INDEX(tblGapAnalysis[Sales_Achievement],MATCH(LARGE(tblGapAnalysis[Sales_Gap],5),tblGapAnalysis[Sales_Gap],0)) -> 1.2250178 | F28: =INDEX(tblGapAnalysis[Status],MATCH(LARGE(tblGapAnalysis[Sales_Gap],5),tblGapAnalysis[Sales_Gap],0)) -> Critical
B30: BOTTOM 5 REPS BY SALES GAP (FURTHEST BELOW TARGET)
B31: Rep Name | C31: Region | D31: Sales Gap | E31: Achievement % | F31: Status
B32: =INDEX(tblGapAnalysis[Rep_Name],MATCH(SMALL(tblGapAnalysis[Sales_Gap],1),tblGapAnalysis[Sales_Gap],0)) -> Soraya Fulton | C32: =INDEX(tblGapAnalysis[Region],MATCH(SMALL(tblGapAnalysis[Sales_Gap],1),tblGapAnalysis[Sales_Gap],0)) -> West | D32: =SMALL(tblGapAnalysis[Sales_Gap],1) -> -336745.54 | E32: =INDEX(tblGapAnalysis[Sales_Achievement],MATCH(SMALL(tblGapAnalysis[Sales_Gap],1),tblGapAnalysis[Sales_Gap],0)) -> 0.32774945 | F32: =INDEX(tblGapAnalysis[Status],MATCH(SMALL(tblGapAnalysis[Sales_Gap],1),tblGapAnalysis[Sales_Gap],0)) -> Critical
B33: =INDEX(tblGapAnalysis[Rep_Name],MATCH(SMALL(tblGapAnalysis[Sales_Gap],2),tblGapAnalysis[Sales_Gap],0)) -> Kathleen Lalonde | C33: =INDEX(tblGapAnalysis[Region],MATCH(SMALL(tblGapAnalysis[Sales_Gap],2),tblGapAnalysis[Sales_Gap],0)) -> Midwest | D33: =SMALL(tblGapAnalysis[Sales_Gap],2) -> -107017.24 | E33: =INDEX(tblGapAnalysis[Sales_Achievement],MATCH(SMALL(tblGapAnalysis[Sales_Gap],2),tblGapAnalysis[Sales_Gap],0)) -> 0.29090909 | F33: =INDEX(tblGapAnalysis[Status],MATCH(SMALL(tblGapAnalysis[Sales_Gap],2),tblGapAnalysis[Sales_Gap],0)) -> Critical
B34: =INDEX(tblGapAnalysis[Rep_Name],MATCH(SMALL(tblGapAnalysis[Sales_Gap],3),tblGapAnalysis[Sales_Gap],0)) -> Marquetta Laycock | C34: =INDEX(tblGapAnalysis[Region],MATCH(SMALL(tblGapAnalysis[Sales_Gap],3),tblGapAnalysis[Sales_Gap],0)) -> West | D34: =SMALL(tblGapAnalysis[Sales_Gap],3) -> -88461.817 | E34: =INDEX(tblGapAnalysis[Sales_Achievement],MATCH(SMALL(tblGapAnalysis[Sales_Gap],3),tblGapAnalysis[Sales_Gap],0)) -> 0.50853614 | F34: =INDEX(tblGapAnalysis[Status],MATCH(SMALL(tblGapAnalysis[Sales_Gap],3),tblGapAnalysis[Sales_Gap],0)) -> Critical
B35: =INDEX(tblGapAnalysis[Rep_Name],MATCH(SMALL(tblGapAnalysis[Sales_Gap],4),tblGapAnalysis[Sales_Gap],0)) -> Dawna Agnew | C35: =INDEX(tblGapAnalysis[Region],MATCH(SMALL(tblGapAnalysis[Sales_Gap],4),tblGapAnalysis[Sales_Gap],0)) -> West | D35: =SMALL(tblGapAnalysis[Sales_Gap],4) -> -80403.05 | E35: =INDEX(tblGapAnalysis[Sales_Achievement],MATCH(SMALL(tblGapAnalysis[Sales_Gap],4),tblGapAnalysis[Sales_Gap],0)) -> 0.83636364 | F35: =INDEX(tblGapAnalysis[Status],MATCH(SMALL(tblGapAnalysis[Sales_Gap],4),tblGapAnalysis[Sales_Gap],0)) -> At Risk
B36: =INDEX(tblGapAnalysis[Rep_Name],MATCH(SMALL(tblGapAnalysis[Sales_Gap],5),tblGapAnalysis[Sales_Gap],0)) -> Carletta Kosinski | C36: =INDEX(tblGapAnalysis[Region],MATCH(SMALL(tblGapAnalysis[Sales_Gap],5),tblGapAnalysis[Sales_Gap],0)) -> Midwest | D36: =SMALL(tblGapAnalysis[Sales_Gap],5) -> -78888.715 | E36: =INDEX(tblGapAnalysis[Sales_Achievement],MATCH(SMALL(tblGapAnalysis[Sales_Gap],5),tblGapAnalysis[Sales_Gap],0)) -> 0.22785908 | F36: =INDEX(tblGapAnalysis[Status],MATCH(SMALL(tblGapAnalysis[Sales_Gap],5),tblGapAnalysis[Sales_Gap],0)) -> Critical
B38: KEY FINDINGS
B39: • Overall achievement (~92%) looks close to target, but that average masks a bimodal sales force: 16 reps are Healthy, 9 are At Risk, and 25 - half the team - are Critical. A single company-wide average would have hidden this split.
B40: • Northeast (99.6%) and Southeast (97.5%) are close to target as regions, while Midwest (78.3%) and West (85.0%) lag on sales achievement. Merchandising compliance does not track the same ranking, though: Northeast, the top-achieving region on sales, has the lowest average merchandising compliance of the four regions (71.3%), while West, the second-weakest region on sales, has the highest (78.1%). Regional sales performance and regional execution quality are not moving together.
B41: • Visit completion (79%) trails attendance, and both average merchandising compliance (74%) and product availability (76%) sit roughly 15-20 percentage points below their 90%/95% targets across the whole sales force - execution quality, not just visit volume, is the more common shortfall.
B42: • The relationship between merchandising compliance and sales achievement is positive but weak (correlation ~0.22) at the whole-portfolio level. That means execution quality is not the whole story: some reps with strong merchandising still miss target, and some reps hit target despite weak execution, so each Critical rep needs to be read individually rather than assumed to be one root cause.
B43: • A distinct subset of reps combines a large negative Sales Gap with merchandising and availability both below ~75% (e.g. Marquetta Laycock, Carletta Kosinski, Nakesha Renn, Babette Soukup, Derrick Boggess) - for these reps, weak field execution is plausibly contributing to the sales shortfall.
B44: • At least one rep (Soraya Fulton, West) shows a large negative Sales Gap (-$337K, 33% achievement) while merchandising and availability are both healthy (88-91%) - this looks like a commercial issue (territory, pricing, account mix) rather than a field-execution problem.
B46: FINDINGS → RECOMMENDATIONS
B47: Finding | E47: Recommended Action
B48: Reps flagged Critical with low merchandising AND low availability (e.g. Marquetta Laycock, Carletta Kosinski, Nakesha Renn) show weak execution alongside weak sales. | E48: Prioritize merchandising audits and supervisor ride-alongs for these reps before adding visit volume; pair with a supply/availability check at their outlets.
...

Sheet README
A1: Field Force & Trade Marketing Performance Dashboard
A3: BUSINESS PROBLEM
A4: Market Express needs visibility into which regions and sales representatives are underperforming, and whether shortfalls are driven by weak selling, poor field execution (visits, merchandising, availability), or both.
A6: OBJECTIVE
A7: Combine real commercial data with a field-execution layer to answer: Which reps/regions are below target? Is the gap commercial or operational? Where should management focus attention?
A9: DATASET
A10: Real data: orders.csv, accounts.csv, sales_reps.csv, region.csv — the 'Sales Dataset of Different Regions' (Parch & Posey schema) from Kaggle. Contains 4,050 orders, 351 accounts, 50 sales reps, 4 regions, spanning Dec 2013–Jan 2017.
A11: Simulated data: field_force_operational_data.xlsx — Working_Days, Attendance_Days, Planned_Visits, Completed_Visits, Merchandising_Compliance, Product_Availability, Target_Multiplier for 50 reps x 25 months (Jan 2015–Jan 2017). This layer does not exist in the public dataset and was built to demonstrate how an analyst would combine commercial and field-execution data.
A13: DATA MODEL
A14: Region -> Sales Rep -> Account -> Order (via region_id, sales_rep_id, account_id foreign keys).
A16: WORKBOOK STRUCTURE
A17: Raw_Orders / Raw_Accounts / Raw_Reps / Raw_Regions — unmodified source tables, loaded as Excel Tables.
... A43: The public dataset contains sales, accounts, regions and sales representative information only. Field-force operational metrics (attendance, planned/completed visits, merchandising compliance, product availability) were SIMULATED for portfolio purposes and should not be interpreted as real Market Express data. All simulated cells are shown in blue font throughout the workbook. Real, formula-derived cells are black.

Sheet Gap_Analysis
A1: Rep_ID | B1: Rep_Name | C1: Region | D1: Total_Actual_Sales | E1: Total_Target | F1: Sales_Gap | G1: Sales_Achievement | H1: Total_Completed_Visits | I1: Total_Planned_Visits | J1: Visit_Gap | K1: Visit_Completion_Rate | L1: Avg_Merchandising | M1: Merchandising_Gap | N1: Avg_Availability | O1: Availability_Gap | P1: Status
A2: =Raw_Reps!A42 -> 321900 | B2: =Raw_Reps!B42 -> Soraya Fulton | C2: =INDEX(tblRegions[name],MATCH(Raw_Reps!C42,tblRegions[id],0)) -> West | D2: =SUMIF(tblOperational[Rep_ID],A2,tblOperational[Actual_Sales]) -> 164177.13 | E2: =SUMIF(tblOperational[Rep_ID],A2,tblOperational[Target]) -> 500922.67 | F2: =D2-E2 -> -336745.54 | G2: =IFERROR(D2/E2,0) -> 0.32774945 | H2: =SUMIF(tblOperational[Rep_ID],A2,tblOperational[Completed_Visits]) -> 12528 | I2: =SUMIF(tblOperational[Rep_ID],A2,tblOperational[Planned_Visits]) -> 13788 | J2: =H2-I2 -> -1260 | K2: =H2/I2 -> 0.90861619 | L2: =AVERAGEIF(tblOperational[Rep_ID],A2,tblOperational[Merchandising_Compliance]) -> 0.876004 | M2: =L2-0.9 -> -0.023996 | N2: =AVERAGEIF(tblOperational[Rep_ID],A2,tblOperational[Product_Availability]) -> 0.91062 | O2: =N2-0.95 -> -0.03938 | P2: =IF(AND(G2>=0.9,L2>=0.8),"Healthy",IF(OR(G2<0.8,L2<0.7),"Critical","At Risk")) -> Critical
A3: =Raw_Reps!A29 -> 321770 | B3: =Raw_Reps!B29 -> Kathleen Lalonde | C3: =INDEX(tblRegions[name],MATCH(Raw_Reps!C29,tblRegions[id],0)) -> Midwest | D3: =SUMIF(tblOperational[Rep_ID],A3,tblOperational[Actual_Sales]) -> 43904.51 | E3: =SUMIF(tblOperational[Rep_ID],A3,tblOperational[Target]) -> 150921.75 | F3: =D3-E3 -> -107017.24 | G3: =IFERROR(D3/E3,0) -> 0.29090909 | H3: =SUMIF(tblOperational[Rep_ID],A3,tblOperational[Completed_Visits]) -> 12010 | I3: =SUMIF(tblOperational[Rep_ID],A3,tblOperational[Planned_Visits]) -> 14088 | J3: =H3-I3 -> -2078 | K3: =H3/I3 -> 0.85249858 | L3: =AVERAGEIF(tblOperational[Rep_ID],A3,tblOperational[Merchandising_Compliance]) -> 0.78688 | M3: =L3-0.9 -> -0.11312 | N3: =AVERAGEIF(tblOperational[Rep_ID],A3,tblOperational[Product_Availability]) -> 0.824932 | O3: =N3-0.95 -> -0.125068 | P3: =IF(AND(G3>=0.9,L3>=0.8),"Healthy",IF(OR(G3<0.8,L3<0.7),"Critical","At Risk")) -> Critical
A4: =Raw_Reps!A44 -> 321920 | B4: =Raw_Reps!B44 -> Marquetta Laycock | C4: =INDEX(tblRegions[name],MATCH(Raw_Reps!C44,tblRegions[id],0)) -> West | D4: =SUMIF(tblOperational[Rep_ID],A4,tblOperational[Actual_Sales]) -> 91534.77 | E4: =SUMIF(tblOperational[Rep_ID],A4,tblOperational[Target]) -> 179996.59 | F4: =D4-E4 -> -88461.817 | G4: =IFERROR(D4/E4,0) -> 0.50853614 | H4: =SUMIF(tblOperational[Rep_ID],A4,tblOperational[Completed_Visits]) -> 8047 | I4: =SUMIF(tblOperational[Rep_ID],A4,tblOperational[Planned_Visits]) -> 12288 | J4: =H4-I4 -> -4241 | K4: =H4/I4 -> 0.65486654 | L4: =AVERAGEIF(tblOperational[Rep_ID],A4,tblOperational[Merchandising_Compliance]) -> 0.58604 | M4: =L4-0.9 -> -0.31396 | N4: =AVERAGEIF(tblOperational[Rep_ID],A4,tblOperational[Product_Availability]) -> 0.61066 | O4: =N4-0.95 -> -0.33934 | P4: =IF(AND(G4>=0.9,L4>=0.8),"Healthy",IF(OR(G4<0.8,L4<0.7),"Critical","At Risk")) -> Critical
A5: =Raw_Reps!A51 -> 321990 | B5: =Raw_Reps!B51 -> Dawna Agnew | C5: =INDEX(tblRegions[name],MATCH(Raw_Reps!C51,tblRegions[id],0)) -> West | D5: =SUMIF(tblOperational[Rep_ID],A5,tblOperational[Actual_Sales]) -> 410948.92 | E5: =SUMIF(tblOperational[Rep_ID],A5,tblOperational[Target]) -> 491351.97 | F5: =D5-E5 -> -80403.05 | G5: =IFERROR(D5/E5,0) -> 0.83636364 | H5: =SUMIF(tblOperational[Rep_ID],A5,tblOperational[Completed_Visits]) -> 9586 | I5: =SUMIF(tblOperational[Rep_ID],A5,tblOperational[Planned_Visits]) -> 12288 | J5: =H5-I5 -> -2702 | K5: =H5/I5 -> 0.78011068 | L5: =AVERAGEIF(tblOperational[Rep_ID],A5,tblOperational[Merchandising_Compliance]) -> 0.72444 | M5: =L5-0.9 -> -0.17556 | N5: =AVERAGEIF(tblOperational[Rep_ID],A5,tblOperational[Product_Availability]) -> 0.753608 | O5: =N5-0.95 -> -0.196392 | P5: =IF(AND(G5>=0.9,L5>=0.8),"Healthy",IF(OR(G5<0.8,L5<0.7),"Critical","At Risk")) -> At Risk
A6: =Raw_Reps!A25 -> 321730 | B6: =Raw_Reps!B25 -> Carletta Kosinski | C6: =INDEX(tblRegions[name],MATCH(Raw_Reps!C25,tblRegions[id],0)) -> Midwest | D6: =SUMIF(tblOperational[Rep_ID],A6,tblOperational[Actual_Sales]) -> 23280.09 | E6: =SUMIF(tblOperational[Rep_ID],A6,tblOperational[Target]) -> 102168.8 | F6: =D6-E6 -> -78888.715 | G6: =IFERROR(D6/E6,0) -> 0.22785908 | H6: =SUMIF(tblOperational[Rep_ID],A6,tblOperational[Completed_Visits]) -> 9618 | I6: =SUMIF(tblOperational[Rep_ID],A6,tblOperational[Planned_Visits]) -> 12888 | J6: =H6-I6 -> -3270 | K6: =H6/I6 -> 0.74627561 | L6: =AVERAGEIF(tblOperational[Rep_ID],A6,tblOperational[Merchandising_Compliance]) -> 0.681952 | M6: =L6-0.9 -> -0.218048 | N6: =AVERAGEIF(tblOperational[Rep_ID],A6,tblOperational[Product_Availability]) -> 0.72588 | O6: =N6-0.95 -> -0.22412 | P6: =IF(AND(G6>=0.9,L6>=0.8),"Healthy",IF(OR(G6<0.8,L6<0.7),"Critical","At Risk")) -> Critical
A7: =Raw_Reps!A19 -> 321670 | B7: =Raw_Reps!B19 -> Nakesha Renn | C7: =INDEX(tblRegions[name],MATCH(Raw_Reps!C19,tblRegions[id],0)) -> Northeast | D7: =SUMIF(tblOperational[Rep_ID],A7,tblOperational[Actual_Sales]) -> 15717.12 | E7: =SUMIF(tblOperational[Rep_ID],A7,tblOperational[Target]) -> 86727.068 | F7: =D7-E7 -> -71009.948 | G7: =IFERROR(D7/E7,0) -> 0.18122508 | H7: =SUMIF(tblOperational[Rep_ID],A7,tblOperational[Completed_Visits]) -> 7903 | I7: =SUMIF(tblOperational[Rep_ID],A7,tblOperational[Planned_Visits]) -> 13188 | J7: =H7-I7 -> -5285 | K7: =H7/I7 -> 0.5992569 | L7: =AVERAGEIF(tblOperational[Rep_ID],A7,tblOperational[Merchandising_Compliance]) -> 0.515632 | M7: =L7-0.9 -> -0.384368 | N7: =AVERAGEIF(tblOperational[Rep_ID],A7,tblOperational[Product_Availability]) -> 0.557656 | O7: =N7-0.95 -> -0.392344 | P7: =IF(AND(G7>=0.9,L7>=0.8),"Healthy",IF(OR(G7<0.8,L7<0.7),"Critical","At Risk")) -> Critical
A8: =Raw_Reps!A45 -> 321930 | B8: =Raw_Reps!B45 -> Hilma Busick | C8: =INDEX(tblRegions[name],MATCH(Raw_Reps!C45,tblRegions[id],0)) -> West | D8: =SUMIF(tblOperational[Rep_ID],A8,tblOperational[Actual_Sales]) -> 130558.53 | E8: =SUMIF(tblOperational[Rep_ID],A8,tblOperational[Target]) -> 189790.87 | F8: =D8-E8 -> -59232.344 | G8: =IFERROR(D8/E8,0) -> 0.68790731 | H8: =SUMIF(tblOperational[Rep_ID],A8,tblOperational[Completed_Visits]) -> 10196 | I8: =SUMIF(tblOperational[Rep_ID],A8,tblOperational[Planned_Visits]) -> 12588 | J8: =H8-I8 -> -2392 | K8: =H8/I8 -> 0.80997776 | L8: =AVERAGEIF(tblOperational[Rep_ID],A8,tblOperational[Merchandising_Compliance]) -> 0.766488 | M8: =L8-0.9 -> -0.133512 | N8: =AVERAGEIF(tblOperational[Rep_ID],A8,tblOperational[Product_Availability]) -> 0.796848 | O8: =N8-0.95 -> -0.153152 | P8: =IF(AND(G8>=0.9,L8>=0.8),"Healthy",IF(OR(G8<0.8,L8<0.7),"Critical","At Risk")) -> Critical
A9: =Raw_Reps!A18 -> 321660 | B9: =Raw_Reps!B18 -> Silvana Virden | C9: =INDEX(tblRegions[name],MATCH(Raw_Reps!C18,tblRegions[id],0)) -> Northeast | D9: =SUMIF(tblOperational[Rep_ID],A9,tblOperational[Actual_Sales]) -> 94772.32 | E9: =SUMIF(tblOperational[Rep_ID],A9,tblOperational[Target]) -> 153308.16 | F9: =D9-E9 -> -58535.845 | G9: =IFERROR(D9/E9,0) -> 0.61818182 | H9: =SUMIF(tblOperational[Rep_ID],A9,tblOperational[Completed_Visits]) -> 10794 | I9: =SUMIF(tblOperational[Rep_ID],A9,tblOperational[Planned_Visits]) -> 12888 | J9: =H9-I9 -> -2094 | K9: =H9/I9 -> 0.83752328 | L9: =AVERAGEIF(tblOperational[Rep_ID],A9,tblOperational[Merchandising_Compliance]) -> 0.797132 | M9: =L9-0.9 -> -0.102868 | N9: =AVERAGEIF(tblOperational[Rep_ID],A9,tblOperational[Product_Availability]) -> 0.824884 | O9: =N9-0.95 -> -0.125116 | P9: =IF(AND(G9>=0.9,L9>=0.8),"Healthy",IF(OR(G9<0.8,L9<0.7),"Critical","At Risk")) -> Critical
A10: =Raw_Reps!A40 -> 321880 | B10: =Raw_Reps!B40 -> Babette Soukup | C10: =INDEX(tblRegions[name],MATCH(Raw_Reps!C40,tblRegions[id],0)) -> Southeast | D10: =SUMIF(tblOperational[Rep_ID],A10,tblOperational[Actual_Sales]) -> 68265.44 | E10: =SUMIF(tblOperational[Rep_ID],A10,tblOperational[Target]) -> 125542.14 | F10: =D10-E10 -> -57276.701 | G10: =IFERROR(D10/E10,0) -> 0.54376514 | H10: =SUMIF(tblOperational[Rep_ID],A10,tblOperational[Completed_Visits]) -> 8342 | I10: =SUMIF(tblOperational[Rep_ID],A10,tblOperational[Planned_Visits]) -> 13188 | J10: =H10-I10 -> -4846 | K10: =H10/I10 -> 0.63254474 | L10: =AVERAGEIF(tblOperational[Rep_ID],A10,tblOperational[Merchandising_Compliance]) -> 0.536896 | M10: =L10-0.9 -> -0.363104 | N10: =AVERAGEIF(tblOperational[Rep_ID],A10,tblOperational[Product_Availability]) -> 0.575612 | O10: =N10-0.95 -> -0.374388 | P10: =IF(AND(G10>=0.9,L10>=0.8),"Healthy",IF(OR(G10<0.8,L10<0.7),"Critical","At Risk")) -> Critical
A11: =Raw_Reps!A39 -> 321870 | B11: =Raw_Reps!B39 -> Derrick Boggess | C11: =INDEX(tblRegions[name],MATCH(Raw_Reps!C39,tblRegions[id],0)) -> Southeast | D11: =SUMIF(tblOperational[Rep_ID],A11,tblOperational[Actual_Sales]) -> 127986.57 | E11: =SUMIF(tblOperational[Rep_ID],A11,tblOperational[Target]) -> 184637.47 | F11: =D11-E11 -> -56650.898 | G11: =IFERROR(D11/E11,0) -> 0.69317767 | H11: =SUMIF(tblOperational[Rep_ID],A11,tblOperational[Completed_Visits]) -> 8155 | I11: =SUMIF(tblOperational[Rep_ID],A11,tblOperational[Planned_Visits]) -> 12888 | J11: =H11-I11 -> -4733 | K11: =H11/I11 -> 0.63275916 | L11: =AVERAGEIF(tblOperational[Rep_ID],A11,tblOperational[Merchandising_Compliance]) -> 0.555204 | M11: =L11-0.9 -> -0.344796 | N11: =AVERAGEIF(tblOperational[Rep_ID],A11,tblOperational[Product_Availability]) -> 0.562784 | O11: =N11-0.95 -> -0.387216 | P11: =IF(AND(G11>=0.9,L11>=0.8),"Healthy",IF(OR(G11<0.8,L11<0.7),"Critical","At Risk")) -> Critical
A12: =Raw_Reps!A35 -> 321830 | B12: =Raw_Reps!B35 -> Maren Musto | C12: =INDEX(tblRegions[name],MATCH(Raw_Reps!C35,tblRegions[id],0)) -> Southeast | D12: =SUMIF(tblOperational[Rep_ID],A12,tblOperational[Actual_Sales]) -> 173222.53 | E12: =SUMIF(tblOperational[Rep_ID],A12,tblOperational[Target]) -> 220091.53 | F12: =D12-E12 -> -46869.003 | G12: =IFERROR(D12/E12,0) -> 0.78704768 | H12: =SUMIF(tblOperational[Rep_ID],A12,tblOperational[Completed_Visits]) -> 8689 | I12: =SUMIF(tblOperational[Rep_ID],A12,tblOperational[Planned_Visits]) -> 13788 | J12: =H12-I12 -> -5099 | K12: =H12/I12 -> 0.63018567 | L12: =AVERAGEIF(tblOperational[Rep_ID],A12,tblOperational[Merchandising_Compliance]) -> 0.561256 | M12: =L12-0.9 -> -0.338744 | N12: =AVERAGEIF(tblOperational[Rep_ID],A12,tblOperational[Product_Availability]) -> 0.571856 | O12: =N12-0.95 -> -0.378144 | P12: =IF(AND(G12>=0.9,L12>=0.8),"Healthy",IF(OR(G12<0.8,L12<0.7),"Critical","At Risk")) -> Critical
A13: =Raw_Reps!A23 -> 321710 | B13: =Raw_Reps!B23 -> Sherlene Wetherington | C13: =INDEX(tblRegions[name],MATCH(Raw_Reps!C23,tblRegions[id],0)) -> Midwest | D13: =SUMIF(tblOperational[Rep_ID],A13,tblOperational[Actual_Sales]) -> 104177.49 | E13: =SUMIF(tblOperational[Rep_ID],A13,tblOperational[Target]) -> 137018.2 | F13: =D13-E13 -> -32840.714 | G13: =IFERROR(D13/E13,0) -> 0.76031861 | H13: =SUMIF(tblOperational[Rep_ID],A13,tblOperational[Completed_Visits]) -> 7908 | I13: =SUMIF(tblOperational[Rep_ID],A13,tblOperational[Planned_Visits]) -> 12288 | J13: =H13-I13 -> -4380 | K13: =H13/I13 -> 0.64355469 | L13: =AVERAGEIF(tblOperational[Rep_ID],A13,tblOperational[Merchandising_Compliance]) -> 0.589692 | M13: =L13-0.9 -> -0.310308 | N13: =AVERAGEIF(tblOperational[Rep_ID],A13,tblOperational[Product_Availability]) -> 0.607452 | O13: =N13-0.95 -> -0.342548 | P13: =IF(AND(G13>=0.9,L13>=0.8),"Healthy",IF(OR(G13<0.8,L13<0.7),"Critical","At Risk")) -> Critical
A14: =Raw_Reps!A30 -> 321780 | B14: =Raw_Reps!B30 -> Julie Starr | C14: =INDEX(tblRegions[name],MATCH(Raw_Reps!C30,tblRegions[id],0)) -> Midwest | D14: =SUMIF(tblOperational[Rep_ID],A14,tblOperational[Actual_Sales]) -> 24241.46 | E14: =SUMIF(tblOperational[Rep_ID],A14,tblOperational[Target]) -> 55048.411 | F14: =D14-E14 -> -30806.951 | G14: =IFERROR(D14/E14,0) -> 0.44036621 | H14: =SUMIF(tblOperational[Rep_ID],A14,tblOperational[Completed_Visits]) -> 10631 | I14: =SUMIF(tblOperational[Rep_ID],A14,tblOperational[Planned_Visits]) -> 12288 | J14: =H14-I14 -> -1657 | K14: =H14/I14 -> 0.86515299 | L14: =AVERAGEIF(tblOperational[Rep_ID],A14,tblOperational[Merchandising_Compliance]) -> 0.796268 | M14: =L14-0.9 -> -0.103732 | N14: =AVERAGEIF(tblOperational[Rep_ID],A14,tblOperational[Product_Availability]) -> 0.839784 | O14: =N14-0.95 -> -0.110216 | P14: =IF(AND(G14>=0.9,L14>=0.8),"Healthy",IF(OR(G14<0.8,L14<0.7),"Critical","At Risk")) -> Critical
A15: =Raw_Reps!A14 -> 321620 | B15: =Raw_Reps!B14 -> Retha Sears | C15: =INDEX(tblRegions[name],MATCH(Raw_Reps!C14,tblRegions[id],0)) -> Northeast | D15: =SUMIF(tblOperational[Rep_ID],A15,tblOperational[Actual_Sales]) -> 53699.03 | E15: =SUMIF(tblOperational[Rep_ID],A15,tblOperational[Target]) -> 81950.686 | F15: =D15-E15 -> -28251.656 | G15: =IFERROR(D15/E15,0) -> 0.65526028 | H15: =SUMIF(tblOperational[Rep_ID],A15,tblOperational[Completed_Visits]) -> 11009 | I15: =SUMIF(tblOperational[Rep_ID],A15,tblOperational[Planned_Visits]) -> 13788 | J15: =H15-I15 -> -2779 | K15: =H15/I15 -> 0.79844793 | L15: =AVERAGEIF(tblOperational[Rep_ID],A15,tblOperational[Merchandising_Compliance]) -> 0.730152 | M15: =L15-0.9 -> -0.169848 | N15: =AVERAGEIF(tblOperational[Rep_ID],A15,tblOperational[Product_Availability]) -> 0.76274 | O15: =N15-0.95 -> -0.18726 | P15: =IF(AND(G15>=0.9,L15>=0.8),"Healthy",IF(OR(G15<0.8,L15<0.7),"Critical","At Risk")) -> Critical
A16: =Raw_Reps!A49 -> 321970 | B16: =Raw_Reps!B49 -> Georgianna Chisholm | C16: =INDEX(tblRegions[name],MATCH(Raw_Reps!C49,tblRegions[id],0)) -> West | D16: =SUMIF(tblOperational[Rep_ID],A16,tblOperational[Actual_Sales]) -> 157954.71 | E16: =SUMIF(tblOperational[Rep_ID],A16,tblOperational[Target]) -> 177260.46 | F16: =D16-E16 -> -19305.751 | G16: =IFERROR(D16/E16,0) -> 0.89108823 | H16: =SUMIF(tblOperational[Rep_ID],A16,tblOperational[Completed_Visits]) -> 11055 | I16: =SUMIF(tblOperational[Rep_ID],A16,tblOperational[Planned_Visits]) -> 13788 | J16: =H16-I16 -> -2733 | K16: =H16/I16 -> 0.80178416 | L16: =AVERAGEIF(tblOperational[Rep_ID],A16,tblOperational[Merchandising_Compliance]) -> 0.765968 | M16: =L16-0.9 -> -0.134032 | N16: =AVERAGEIF(tblOperational[Rep_ID],A16,tblOperational[Product_Availability]) -> 0.794912 | O16: =N16-0.95 -> -0.155088 | P16: =IF(AND(G16>=0.9,L16>=0.8),"Healthy",IF(OR(G16<0.8,L16<0.7),"Critical","At Risk")) -> At Risk
A17: =Raw_Reps!A6 -> 321540 | B17: =Raw_Reps!B6 -> Cara Clarke | C17: =INDEX(tblRegions[name],MATCH(Raw_Reps!C6,tblRegions[id],0)) -> Northeast | D17: =SUMIF(tblOperational[Rep_ID],A17,tblOperational[Actual_Sales]) -> 55061.03 | E17: =SUMIF(tblOperational[Rep_ID],A17,tblOperational[Target]) -> 70483.008 | F17: =D17-E17 -> -15421.978 | G17: =IFERROR(D17/E17,0) -> 0.7811958 | H17: =SUMIF(tblOperational[Rep_ID],A17,tblOperational[Completed_Visits]) -> 7418 | I17: =SUMIF(tblOperational[Rep_ID],A17,tblOperational[Planned_Visits]) -> 13488 | J17: =H17-I17 -> -6070 | K17: =H17/I17 -> 0.54997034 | L17: =AVERAGEIF(tblOperational[Rep_ID],A17,tblOperational[Merchandising_Compliance]) -> 0.4 | M17: =L17-0.9 -> -0.5 | N17: =AVERAGEIF(tblOperational[Rep_ID],A17,tblOperational[Product_Availability]) -> 0.45 | O17: =N17-0.95 -> -0.5 | P17: =IF(AND(G17>=0.9,L17>=0.8),"Healthy",IF(OR(G17<0.8,L17<0.7),"Critical","At Risk")) -> Critical
A18: =Raw_Reps!A41 -> 321890 | B18: =Raw_Reps!B41 -> Nelle Meaux | C18: =INDEX(tblRegions[name],MATCH(Raw_Reps!C41,tblRegions[id],0)) -> Southeast | D18: =SUMIF(tblOperational[Rep_ID],A18,tblOperational[Actual_Sales]) -> 246219.24 | E18: =SUMIF(tblOperational[Rep_ID],A18,tblOperational[Target]) -> 261219.13 | F18: =D18-E18 -> -14999.889 | G18: =IFERROR(D18/E18,0) -> 0.94257737 | H18: =SUMIF(tblOperational[Rep_ID],A18,tblOperational[Completed_Visits]) -> 11988 | I18: =SUMIF(tblOperational[Rep_ID],A18,tblOperational[Planned_Visits]) -> 13488 | J18: =H18-I18 -> -1500 | K18: =H18/I18 -> 0.88879004 | L18: =AVERAGEIF(tblOperational[Rep_ID],A18,tblOperational[Merchandising_Compliance]) -> 0.857844 | M18: =L18-0.9 -> -0.042156 | N18: =AVERAGEIF(tblOperational[Rep_ID],A18,tblOperational[Product_Availability]) -> 0.892224 | O18: =N18-0.95 -> -0.057776 | P18: =IF(AND(G18>=0.9,L18>=0.8),"Healthy",IF(OR(G18<0.8,L18<0.7),"Critical","At Risk")) -> Healthy
A19: =Raw_Reps!A20 -> 321680 | B19: =Raw_Reps!B20 -> Elna Condello | C19: =INDEX(tblRegions[name],MATCH(Raw_Reps!C20,tblRegions[id],0)) -> Northeast | D19: =SUMIF(tblOperational[Rep_ID],A19,tblOperational[Actual_Sales]) -> 180058.73 | E19: =SUMIF(tblOperational[Rep_ID],A19,tblOperational[Target]) -> 192464.91 | F19: =D19-E19 -> -12406.176 | G19: =IFERROR(D19/E19,0) -> 0.93554058 | H19: =SUMIF(tblOperational[Rep_ID],A19,tblOperational[Completed_Visits]) -> 12369 | I19: =SUMIF(tblOperational[Rep_ID],A19,tblOperational[Planned_Visits]) -> 13488 | J19: =H19-I19 -> -1119 | K19: =H19/I19 -> 0.91703737 | L19: =AVERAGEIF(tblOperational[Rep_ID],A19,tblOperational[Merchandising_Compliance]) -> 0.882404 | M19: =L19-0.9 -> -0.017596 | N19: =AVERAGEIF(tblOperational[Rep_ID],A19,tblOperational[Product_Availability]) -> 0.93276 | O19: =N19-0.95 -> -0.01724 | P19: =IF(AND(G19>=0.9,L19>=0.8),"Healthy",IF(OR(G19<0.8,L19<0.7),"Critical","At Risk")) -> Healthy
A20: =Raw_Reps!A24 -> 321720 | B20: =Raw_Reps!B24 -> Chau Rowles | C20: =INDEX(tblRegions[name],MATCH(Raw_Reps!C24,tblRegions[id],0)) -> Midwest | D20: =SUMIF(tblOperational[Rep_ID],A20,tblOperational[Actual_Sales]) -> 60449.2 | E20: =SUMIF(tblOperational[Rep_ID],A20,tblOperational[Target]) -> 70720.486 | F20: =D20-E20 -> -10271.286 | G20: =IFERROR(D20/E20,0) -> 0.85476222 | H20: =SUMIF(tblOperational[Rep_ID],A20,tblOperational[Completed_Visits]) -> 12294 | I20: =SUMIF(tblOperational[Rep_ID],A20,tblOperational[Planned_Visits]) -> 12588 | J20: =H20-I20 -> -294 | K20: =H20/I20 -> 0.97664442 | L20: =AVERAGEIF(tblOperational[Rep_ID],A20,tblOperational[Merchandising_Compliance]) -> 0.956556 | M20: =L20-0.9 -> 0.056556 | N20: =AVERAGEIF(tblOperational[Rep_ID],A20,tblOperational[Product_Availability]) -> 0.975592 | O20: =N20-0.95 -> 0.025592 | P20: =IF(AND(G20>=0.9,L20>=0.8),"Healthy",IF(OR(G20<0.8,L20<0.7),"Critical","At Risk")) -> At Risk
A21: =Raw_Reps!A17 -> 321650 | B21: =Raw_Reps!B17 -> Akilah Drinkard | C21: =INDEX(tblRegions[name],MATCH(Raw_Reps!C17,tblRegions[id],0)) -> Northeast | D21: =SUMIF(tblOperational[Rep_ID],A21,tblOperational[Actual_Sales]) -> 83872.45 | E21: =SUMIF(tblOperational[Rep_ID],A21,tblOperational[Target]) -> 93989.759 | F21: =D21-E21 -> -10117.309 | G21: =IFERROR(D21/E21,0) -> 0.89235732 | H21: =SUMIF(tblOperational[Rep_ID],A21,tblOperational[Completed_Visits]) -> 7823 | I21: =SUMIF(tblOperational[Rep_ID],A21,tblOperational[Planned_Visits]) -> 12588 | J21: =H21-I21 -> -4765 | K21: =H21/I21 -> 0.62146489 | L21: =AVERAGEIF(tblOperational[Rep_ID],A21,tblOperational[Merchandising_Compliance]) -> 0.544456 | M21: =L21-0.9 -> -0.355544 | N21: =AVERAGEIF(tblOperational[Rep_ID],A21,tblOperational[Product_Availability]) -> 0.569136 | O21: =N21-0.95 -> -0.380864 | P21: =IF(AND(G21>=0.9,L21>=0.8),"Healthy",IF(OR(G21<0.8,L21<0.7),"Critical","At Risk")) -> Critical
A22: =Raw_Reps!A28 -> 321760 | B22: =Raw_Reps!B28 -> Delilah Krum | C22: =INDEX(tblRegions[name],MATCH(Raw_Reps!C28,tblRegions[id],0)) -> Midwest | D22: =SUMIF(tblOperational[Rep_ID],A22,tblOperational[Actual_Sales]) -> 223979.95 | E22: =SUMIF(tblOperational[Rep_ID],A22,tblOperational[Target]) -> 233909.45 | F22: =D22-E22 -> -9929.5004 | G22: =IFERROR(D22/E22,0) -> 0.95754981 | H22: =SUMIF(tblOperational[Rep_ID],A22,tblOperational[Completed_Visits]) -> 11902 | I22: =SUMIF(tblOperational[Rep_ID],A22,tblOperational[Planned_Visits]) -> 13788 | J22: =H22-I22 -> -1886 | K22: =H22/I22 -> 0.86321439 | L22: =AVERAGEIF(tblOperational[Rep_ID],A22,tblOperational[Merchandising_Compliance]) -> 0.835272 | M22: =L22-0.9 -> -0.064728 | N22: =AVERAGEIF(tblOperational[Rep_ID],A22,tblOperational[Product_Availability]) -> 0.855976 | O22: =N22-0.95 -> -0.094024 | P22: =IF(AND(G22>=0.9,L22>=0.8),"Healthy",IF(OR(G22<0.8,L22<0.7),"Critical","At Risk")) -> Healthy
A23: =Raw_Reps!A26 -> 321740 | B23: =Raw_Reps!B26 -> Charles Bidwell | C23: =INDEX(tblRegions[name],MATCH(Raw_Reps!C26,tblRegions[id],0)) -> Midwest | D23: =SUMIF(tblOperational[Rep_ID],A23,tblOperational[Actual_Sales]) -> 219821.47 | E23: =SUMIF(tblOperational[Rep_ID],A23,tblOperational[Target]) -> 228489.56 | F23: =D23-E23 -> -8668.0917 | G23: =IFERROR(D23/E23,0) -> 0.96206351 | H23: =SUMIF(tblOperational[Rep_ID],A23,tblOperational[Completed_Visits]) -> 9350 | I23: =SUMIF(tblOperational[Rep_ID],A23,tblOperational[Planned_Visits]) -> 13188 | J23: =H23-I23 -> -3838 | K23: =H23/I23 -> 0.70897786 | L23: =AVERAGEIF(tblOperational[Rep_ID],A23,tblOperational[Merchandising_Compliance]) -> 0.642748 | M23: =L23-0.9 -> -0.257252 | N23: =AVERAGEIF(tblOperational[Rep_ID],A23,tblOperational[Product_Availability]) -> 0.657548 | O23: =N23-0.95 -> -0.292452 | P23: =IF(AND(G23>=0.9,L23>=0.8),"Healthy",IF(OR(G23<0.8,L23<0.7),"Critical","At Risk")) -> Critical
A24: =Raw_Reps!A27 -> 321750 | B24: =Raw_Reps!B27 -> Cliff Meints | C24: =INDEX(tblRegions[name],MATCH(Raw_Reps!C27,tblRegions[id],0)) -> Midwest | D24: =SUMIF(tblOperational[Rep_ID],A24,tblOperational[Actual_Sales]) -> 236912.67 | E24: =SUMIF(tblOperational[Rep_ID],A24,tblOperational[Target]) -> 243989.93 | F24: =D24-E24 -> -7077.2553 | G24: =IFERROR(D24/E24,0) -> 0.97099366 | H24: =SUMIF(tblOperational[Rep_ID],A24,tblOperational[Completed_Visits]) -> 9912 | I24: =SUMIF(tblOperational[Rep_ID],A24,tblOperational[Planned_Visits]) -> 13488 | J24: =H24-I24 -> -3576 | K24: =H24/I24 -> 0.73487544 | L24: =AVERAGEIF(tblOperational[Rep_ID],A24,tblOperational[Merchandising_Compliance]) -> 0.649616 | M24: =L24-0.9 -> -0.250384 | N24: =AVERAGEIF(tblOperational[Rep_ID],A24,tblOperational[Product_Availability]) -> 0.678732 | O24: =N24-0.95 -> -0.271268 | P24: =IF(AND(G24>=0.9,L24>=0.8),"Healthy",IF(OR(G24<0.8,L24<0.7),"Critical","At Risk")) -> Critical
A25: =Raw_Reps!A7 -> 321550 | B25: =Raw_Reps!B7 -> Lavera Oles | C25: =INDEX(tblRegions[name],MATCH(Raw_Reps!C7,tblRegions[id],0)) -> Northeast | D25: =SUMIF(tblOperational[Rep_ID],A25,tblOperational[Actual_Sales]) -> 90920.19 | E25: =SUMIF(tblOperational[Rep_ID],A25,tblOperational[Target]) -> 96601.419 | F25: =D25-E25 -> -5681.2294 | G25: =IFERROR(D25/E25,0) -> 0.94118897 | H25: =SUMIF(tblOperational[Rep_ID],A25,tblOperational[Completed_Visits]) -> 7732 | I25: =SUMIF(tblOperational[Rep_ID],A25,tblOperational[Planned_Visits]) -> 13788 | J25: =H25-I25 -> -6056 | K25: =H25/I25 -> 0.56077749 | L25: =AVERAGEIF(tblOperational[Rep_ID],A25,tblOperational[Merchandising_Compliance]) -> 0.455752 | M25: =L25-0.9 -> -0.444248 | N25: =AVERAGEIF(tblOperational[Rep_ID],A25,tblOperational[Product_Availability]) -> 0.482704 | O25: =N25-0.95 -> -0.467296 | P25: =IF(AND(G25>=0.9,L25>=0.8),"Healthy",IF(OR(G25<0.8,L25<0.7),"Critical","At Risk")) -> Critical
A26: =Raw_Reps!A5 -> 321530 | B26: =Raw_Reps!B5 -> Renetta Carew | C26: =INDEX(tblRegions[name],MATCH(Raw_Reps!C5,tblRegions[id],0)) -> Northeast | D26: =SUMIF(tblOperational[Rep_ID],A26,tblOperational[Actual_Sales]) -> 78258.44 | E26: =SUMIF(tblOperational[Rep_ID],A26,tblOperational[Target]) -> 83596.353 | F26: =D26-E26 -> -5337.9132 | G26: =IFERROR(D26/E26,0) -> 0.93614658 | H26: =SUMIF(tblOperational[Rep_ID],A26,tblOperational[Completed_Visits]) -> 12505 | I26: =SUMIF(tblOperational[Rep_ID],A26,tblOperational[Planned_Visits]) -> 13188 | J26: =H26-I26 -> -683 | K26: =H26/I26 -> 0.94821049 | L26: =AVERAGEIF(tblOperational[Rep_ID],A26,tblOperational[Merchandising_Compliance]) -> 0.90224 | M26: =L26-0.9 -> 0.00224 | N26: =AVERAGEIF(tblOperational[Rep_ID],A26,tblOperational[Product_Availability]) -> 0.942612 | O26: =N26-0.95 -> -0.007388 | P26: =IF(AND(G26>=0.9,L26>=0.8),"Healthy",IF(OR(G26<0.8,L26<0.7),"Critical","At Risk")) -> Healthy
A27: =Raw_Reps!A8 -> 321560 | B27: =Raw_Reps!B8 -> Elba Felder | C27: =INDEX(tblRegions[name],MATCH(Raw_Reps!C8,tblRegions[id],0)) -> Northeast | D27: =SUMIF(tblOperational[Rep_ID],A27,tblOperational[Actual_Sales]) -> 29775.22 | E27: =SUMIF(tblOperational[Rep_ID],A27,tblOperational[Target]) -> 34173.693 | F27: =D27-E27 -> -4398.473 | G27: =IFERROR(D27/E27,0) -> 0.87129067 | H27: =SUMIF(tblOperational[Rep_ID],A27,tblOperational[Completed_Visits]) -> 11202 | I27: =SUMIF(tblOperational[Rep_ID],A27,tblOperational[Planned_Visits]) -> 14088 | J27: =H27-I27 -> -2886 | K27: =H27/I27 -> 0.7951448 | L27: =AVERAGEIF(tblOperational[Rep_ID],A27,tblOperational[Merchandising_Compliance]) -> 0.74272 | M27: =L27-0.9 -> -0.15728 | N27: =AVERAGEIF(tblOperational[Rep_ID],A27,tblOperational[Product_Availability]) -> 0.767744 | O27: =N27-0.95 -> -0.182256 | P27: =IF(AND(G27>=0.9,L27>=0.8),"Healthy",IF(OR(G27<0.8,L27<0.7),"Critical","At Risk")) -> At Risk
A28: =Raw_Reps!A33 -> 321810 | B28: =Raw_Reps!B33 -> Moon Torian | C28: =INDEX(tblRegions[name],MATCH(Raw_Reps!C33,tblRegions[id],0)) -> Southeast | D28: =SUMIF(tblOperational[Rep_ID],A28,tblOperational[Actual_Sales]) -> 341111.93 | E28: =SUMIF(tblOperational[Rep_ID],A28,tblOperational[Target]) -> 343670.09 | F28: =D28-E28 -> -2558.1585 | G28: =IFERROR(D28/E28,0) -> 0.99255635 | H28: =SUMIF(tblOperational[Rep_ID],A28,tblOperational[Completed_Visits]) -> 9267 | I28: =SUMIF(tblOperational[Rep_ID],A28,tblOperational[Planned_Visits]) -> 13188 | J28: =H28-I28 -> -3921 | K28: =H28/I28 -> 0.70268426 | L28: =AVERAGEIF(tblOperational[Rep_ID],A28,tblOperational[Merchandising_Compliance]) -> 0.647812 | M28: =L28-0.9 -> -0.252188 | N28: =AVERAGEIF(tblOperational[Rep_ID],A28,tblOperational[Product_Availability]) -> 0.657172 | O28: =N28-0.95 -> -0.292828 | P28: =IF(AND(G28>=0.9,L28>=0.8),"Healthy",IF(OR(G28<0.8,L28<0.7),"Critical","At Risk")) -> Critical
A29: =Raw_Reps!A15 -> 321630 | B29: =Raw_Reps!B15 -> Julia Behrman | C29: =INDEX(tblRegions[name],MATCH(Raw_Reps!C15,tblRegions[id],0)) -> Northeast | D29: =SUMIF(tblOperational[Rep_ID],A29,tblOperational[Actual_Sales]) -> 193679.37 | E29: =SUMIF(tblOperational[Rep_ID],A29,tblOperational[Target]) -> 192371.74 | F29: =D29-E29 -> 1307.6303 | G29: =IFERROR(D29/E29,0) -> 1.0067974 | H29: =SUMIF(tblOperational[Rep_ID],A29,tblOperational[Completed_Visits]) -> 13790 | I29: =SUMIF(tblOperational[Rep_ID],A29,tblOperational[Planned_Visits]) -> 14088 | J29: =H29-I29 -> -298 | K29: =H29/I29 -> 0.97884725 | L29: =AVERAGEIF(tblOperational[Rep_ID],A29,tblOperational[Merchandising_Compliance]) -> 0.939876 | M29: =L29-0.9 -> 0.039876 | N29: =AVERAGEIF(tblOperational[Rep_ID],A29,tblOperational[Product_Availability]) -> 0.965184 | O29: =N29-0.95 -> 0.015184 | P29: =IF(AND(G29>=0.9,L29>=0.8),"Healthy",IF(OR(G29<0.8,L29<0.7),"Critical","At Risk")) -> Healthy
A30: =Raw_Reps!A31 -> 321790 | B30: =Raw_Reps!B31 -> Cordell Rieder | C30: =INDEX(tblRegions[name],MATCH(Raw_Reps!C31,tblRegions[id],0)) -> Midwest | D30: =SUMIF(tblOperational[Rep_ID],A30,tblOperational[Actual_Sales]) -> 84700.04 | E30: =SUMIF(tblOperational[Rep_ID],A30,tblOperational[Target]) -> 82808.219 | F30: =D30-E30 -> 1891.8209 | G30: =IFERROR(D30/E30,0) -> 1.0228458 | H30: =SUMIF(tblOperational[Rep_ID],A30,tblOperational[Completed_Visits]) -> 10806 | I30: =SUMIF(tblOperational[Rep_ID],A30,tblOperational[Planned_Visits]) -> 12588 | J30: =H30-I30 -> -1782 | K30: =H30/I30 -> 0.85843661 | L30: =AVERAGEIF(tblOperational[Rep_ID],A30,tblOperational[Merchandising_Compliance]) -> 0.80118 | M30: =L30-0.9 -> -0.09882 | N30: =AVERAGEIF(tblOperational[Rep_ID],A30,tblOperational[Product_Availability]) -> 0.850296 | O30: =N30-0.95 -> -0.099704 | P30: =IF(AND(G30>=0.9,L30>=0.8),"Healthy",IF(OR(G30<0.8,L30<0.7),"Critical","At Risk")) -> Healthy
A31: =Raw_Reps!A38 -> 321860 | B31: =Raw_Reps!B38 -> Saran Ram | C31: =INDEX(tblRegions[name],MATCH(Raw_Reps!C38,tblRegions[id],0)) -> Southeast | D31: =SUMIF(tblOperational[Rep_ID],A31,tblOperational[Actual_Sales]) -> 157220.51 | E31: =SUMIF(tblOperational[Rep_ID],A31,tblOperational[Target]) -> 155267.71 | F31: =D31-E31 -> 1952.801 | G31: =IFERROR(D31/E31,0) -> 1.012577 | H31: =SUMIF(tblOperational[Rep_ID],A31,tblOperational[Completed_Visits]) -> 9624 | I31: =SUMIF(tblOperational[Rep_ID],A31,tblOperational[Planned_Visits]) -> 12588 | J31: =H31-I31 -> -2964 | K31: =H31/I31 -> 0.76453765 | L31: =AVERAGEIF(tblOperational[Rep_ID],A31,tblOperational[Merchandising_Compliance]) -> 0.69802 | M31: =L31-0.9 -> -0.20198 | N31: =AVERAGEIF(tblOperational[Rep_ID],A31,tblOperational[Product_Availability]) -> 0.731456 | O31: =N31-0.95 -> -0.218544 | P31: =IF(AND(G31>=0.9,L31>=0.8),"Healthy",IF(OR(G31<0.8,L31<0.7),"Critical","At Risk")) -> Critical
A32: =Raw_Reps!A50 -> 321980 | B32: =Raw_Reps!B50 -> Micha Woodford | C32: =INDEX(tblRegions[name],MATCH(Raw_Reps!C50,tblRegions[id],0)) -> West | D32: =SUMIF(tblOperational[Rep_ID],A32,tblOperational[Actual_Sales]) -> 221862.21 | E32: =SUMIF(tblOperational[Rep_ID],A32,tblOperational[Target]) -> 219888.29 | F32: =D32-E32 -> 1973.9228 | G32: =IFERROR(D32/E32,0) -> 1.0089769 | H32: =SUMIF(tblOperational[Rep_ID],A32,tblOperational[Completed_Visits]) -> 12613 | I32: =SUMIF(tblOperational[Rep_ID],A32,tblOperational[Planned_Visits]) -> 14088 | J32: =H32-I32 -> -1475 | K32: =H32/I32 -> 0.89530097 | L32: =AVERAGEIF(tblOperational[Rep_ID],A32,tblOperational[Merchandising_Compliance]) -> 0.854584 | M32: =L32-0.9 -> -0.045416 | N32: =AVERAGEIF(tblOperational[Rep_ID],A32,tblOperational[Product_Availability]) -> 0.897196 | O32: =N32-0.95 -> -0.052804 | P32: =IF(AND(G32>=0.9,L32>=0.8),"Healthy",IF(OR(G32<0.8,L32<0.7),"Critical","At Risk")) -> Healthy
A33: =Raw_Reps!A43 -> 321910 | B33: =Raw_Reps!B43 -> Brandie Riva | C33: =INDEX(tblRegions[name],MATCH(Raw_Reps!C43,tblRegions[id],0)) -> West | D33: =SUMIF(tblOperational[Rep_ID],A33,tblOperational[Actual_Sales]) -> 198796.33 | E33: =SUMIF(tblOperational[Rep_ID],A33,tblOperational[Target]) -> 195449.08 | F33: =D33-E33 -> 3347.2542 | G33: =IFERROR(D33/E33,0) -> 1.017126 | H33: =SUMIF(tblOperational[Rep_ID],A33,tblOperational[Completed_Visits]) -> 12529 | I33: =SUMIF(tblOperational[Rep_ID],A33,tblOperational[Planned_Visits]) -> 14088 | J33: =H33-I33 -> -1559 | K33: =H33/I33 -> 0.88933844 | L33: =AVERAGEIF(tblOperational[Rep_ID],A33,tblOperational[Merchandising_Compliance]) -> 0.833496 | M33: =L33-0.9 -> -0.066504 | N33: =AVERAGEIF(tblOperational[Rep_ID],A33,tblOperational[Product_Availability]) -> 0.866696 | O33: =N33-0.95 -> -0.083304 | P33: =IF(AND(G33>=0.9,L33>=0.8),"Healthy",IF(OR(G33<0.8,L33<0.7),"Critical","At Risk")) -> Healthy
A34: =Raw_Reps!A32 -> 321800 | B34: =Raw_Reps!B32 -> Earlie Schleusner | C34: =INDEX(tblRegions[name],MATCH(Raw_Reps!C32,tblRegions[id],0)) -> Southeast | D34: =SUMIF(tblOperational[Rep_ID],A34,tblOperational[Actual_Sales]) -> 370640.45 | E34: =SUMIF(tblOperational[Rep_ID],A34,tblOperational[Target]) -> 365725.32 | F34: =D34-E34 -> 4915.133 | G34: =IFERROR(D34/E34,0) -> 1.0134394 | H34: =SUMIF(tblOperational[Rep_ID],A34,tblOperational[Completed_Visits]) -> 12763 | I34: =SUMIF(tblOperational[Rep_ID],A34,tblOperational[Planned_Visits]) -> 12888 | J34: =H34-I34 -> -125 | K34: =H34/I34 -> 0.99030106 | L34: =AVERAGEIF(tblOperational[Rep_ID],A34,tblOperational[Merchandising_Compliance]) -> 0.97 | M34: =L34-0.9 -> 0.07 | N34: =AVERAGEIF(tblOperational[Rep_ID],A34,tblOperational[Product_Availability]) -> 0.98 | O34: =N34-0.95 -> 0.03 | P34: =IF(AND(G34>=0.9,L34>=0.8),"Healthy",IF(OR(G34<0.8,L34<0.7),"Critical","At Risk")) -> Healthy
A35: =Raw_Reps!A13 -> 321610 | B35: =Raw_Reps!B13 -> Ayesha Monica | C35: =INDEX(tblRegions[name],MATCH(Raw_Reps!C13,tblRegions[id],0)) -> Northeast | D35: =SUMIF(tblOperational[Rep_ID],A35,tblOperational[Actual_Sales]) -> 111051.82 | E35: =SUMIF(tblOperational[Rep_ID],A35,tblOperational[Target]) -> 105856.31 | F35: =D35-E35 -> 5195.509 | G35: =IFERROR(D35/E35,0) -> 1.0490808 | H35: =SUMIF(tblOperational[Rep_ID],A35,tblOperational[Completed_Visits]) -> 12312 | I35: =SUMIF(tblOperational[Rep_ID],A35,tblOperational[Planned_Visits]) -> 13488 | J35: =H35-I35 -> -1176 | K35: =H35/I35 -> 0.91281139 | L35: =AVERAGEIF(tblOperational[Rep_ID],A35,tblOperational[Merchandising_Compliance]) -> 0.866496 | M35: =L35-0.9 -> -0.033504 | N35: =AVERAGEIF(tblOperational[Rep_ID],A35,tblOperational[Product_Availability]) -> 0.904064 | O35: =N35-0.95 -> -0.045936 | P35: =IF(AND(G35>=0.9,L35>=0.8),"Healthy",IF(OR(G35<0.8,L35<0.7),"Critical","At Risk")) -> Healthy
A36: =Raw_Reps!A9 -> 321570 | B36: =Raw_Reps!B9 -> Shawanda Selke | C36: =INDEX(tblRegions[name],MATCH(Raw_Reps!C9,tblRegions[id],0)) -> Northeast | D36: =SUMIF(tblOperational[Rep_ID],A36,tblOperational[Actual_Sales]) -> 153278.4 | E36: =SUMIF(tblOperational[Rep_ID],A36,tblOperational[Target]) -> 147973.64 | F36: =D36-E36 -> 5304.7574 | G36: =IFERROR(D36/E36,0) -> 1.0358493 | H36: =SUMIF(tblOperational[Rep_ID],A36,tblOperational[Completed_Visits]) -> 8833 | I36: =SUMIF(tblOperational[Rep_ID],A36,tblOperational[Planned_Visits]) -> 12288 | J36: =H36-I36 -> -3455 | K36: =H36/I36 -> 0.71883138 | L36: =AVERAGEIF(tblOperational[Rep_ID],A36,tblOperational[Merchandising_Compliance]) -> 0.652052 | M36: =L36-0.9 -> -0.247948 | N36: =AVERAGEIF(tblOperational[Rep_ID],A36,tblOperational[Product_Availability]) -> 0.693856 | O36: =N36-0.95 -> -0.256144 | P36: =IF(AND(G36>=0.9,L36>=0.8),"Healthy",IF(OR(G36<0.8,L36<0.7),"Critical","At Risk")) -> Critical
A37: =Raw_Reps!A21 -> 321690 | B37: =Raw_Reps!B21 -> Gianna Dossey | C37: =INDEX(tblRegions[name],MATCH(Raw_Reps!C21,tblRegions[id],0)) -> Northeast | D37: =SUMIF(tblOperational[Rep_ID],A37,tblOperational[Actual_Sales]) -> 200272.97 | E37: =SUMIF(tblOperational[Rep_ID],A37,tblOperational[Target]) -> 192241.54 | F37: =D37-E37 -> 8031.4278 | G37: =IFERROR(D37/E37,0) -> 1.0417778 | H37: =SUMIF(tblOperational[Rep_ID],A37,tblOperational[Completed_Visits]) -> 10644 | I37: =SUMIF(tblOperational[Rep_ID],A37,tblOperational[Planned_Visits]) -> 13788 | J37: =H37-I37 -> -3144 | K37: =H37/I37 -> 0.77197563 | L37: =AVERAGEIF(tblOperational[Rep_ID],A37,tblOperational[Merchandising_Compliance]) -> 0.701812 | M37: =L37-0.9 -> -0.198188 | N37: =AVERAGEIF(tblOperational[Rep_ID],A37,tblOperational[Product_Availability]) -> 0.732932 | O37: =N37-0.95 -> -0.217068 | P37: =IF(AND(G37>=0.9,L37>=0.8),"Healthy",IF(OR(G37<0.8,L37<0.7),"Critical","At Risk")) -> At Risk
A38: =Raw_Reps!A2 -> 321500 | B38: =Raw_Reps!B2 -> Samuel Racine | C38: =INDEX(tblRegions[name],MATCH(Raw_Reps!C2,tblRegions[id],0)) -> Northeast | D38: =SUMIF(tblOperational[Rep_ID],A38,tblOperational[Actual_Sales]) -> 133867.33 | E38: =SUMIF(tblOperational[Rep_ID],A38,tblOperational[Target]) -> 119437.17 | F38: =D38-E38 -> 14430.157 | G38: =IFERROR(D38/E38,0) -> 1.120818 | H38: =SUMIF(tblOperational[Rep_ID],A38,tblOperational[Completed_Visits]) -> 10227 | I38: =SUMIF(tblOperational[Rep_ID],A38,tblOperational[Planned_Visits]) -> 12288 | J38: =H38-I38 -> -2061 | K38: =H38/I38 -> 0.83227539 | L38: =AVERAGEIF(tblOperational[Rep_ID],A38,tblOperational[Merchandising_Compliance]) -> 0.773604 | M38: =L38-0.9 -> -0.126396 | N38: =AVERAGEIF(tblOperational[Rep_ID],A38,tblOperational[Product_Availability]) -> 0.810392 | O38: =N38-0.95 -> -0.139608 | P38: =IF(AND(G38>=0.9,L38>=0.8),"Healthy",IF(OR(G38<0.8,L38<0.7),"Critical","At Risk")) -> At Risk
A39: =Raw_Reps!A16 -> 321640 | B39: =Raw_Reps!B16 -> Tia Amato | C39: =INDEX(tblRegions[name],MATCH(Raw_Reps!C16,tblRegions[id],0)) -> Northeast | D39: =SUMIF(tblOperational[Rep_ID],A39,tblOperational[Actual_Sales]) -> 363628.01 | E39: =SUMIF(tblOperational[Rep_ID],A39,tblOperational[Target]) -> 347014.15 | F39: =D39-E39 -> 16613.857 | G39: =IFERROR(D39/E39,0) -> 1.0478766 | H39: =SUMIF(tblOperational[Rep_ID],A39,tblOperational[Completed_Visits]) -> 10580 | I39: =SUMIF(tblOperational[Rep_ID],A39,tblOperational[Planned_Visits]) -> 12288 | J39: =H39-I39 -> -1708 | K39: =H39/I39 -> 0.8610026 | L39: =AVERAGEIF(tblOperational[Rep_ID],A39,tblOperational[Merchandising_Compliance]) -> 0.823324 | M39: =L39-0.9 -> -0.076676 | N39: =AVERAGEIF(tblOperational[Rep_ID],A39,tblOperational[Product_Availability]) -> 0.832368 | O39: =N39-0.95 -> -0.117632 | P39: =IF(AND(G39>=0.9,L39>=0.8),"Healthy",IF(OR(G39<0.8,L39<0.7),"Critical","At Risk")) -> Healthy
A40: =Raw_Reps!A10 -> 321580 | B40: =Raw_Reps!B10 -> Sibyl Lauria | C40: =INDEX(tblRegions[name],MATCH(Raw_Reps!C10,tblRegions[id],0)) -> Northeast | D40: =SUMIF(tblOperational[Rep_ID],A40,tblOperational[Actual_Sales]) -> 218417.18 | E40: =SUMIF(tblOperational[Rep_ID],A40,tblOperational[Target]) -> 199912.81 | F40: =D40-E40 -> 18504.365 | G40: =IFERROR(D40/E40,0) -> 1.0925622 | H40: =SUMIF(tblOperational[Rep_ID],A40,tblOperational[Completed_Visits]) -> 9667 | I40: =SUMIF(tblOperational[Rep_ID],A40,tblOperational[Planned_Visits]) -> 12588 | J40: =H40-I40 -> -2921 | K40: =H40/I40 -> 0.76795361 | L40: =AVERAGEIF(tblOperational[Rep_ID],A40,tblOperational[Merchandising_Compliance]) -> 0.712796 | M40: =L40-0.9 -> -0.187204 | N40: =AVERAGEIF(tblOperational[Rep_ID],A40,tblOperational[Product_Availability]) -> 0.744316 | O40: =N40-0.95 -> -0.205684 | P40: =IF(AND(G40>=0.9,L40>=0.8),"Healthy",IF(OR(G40<0.8,L40<0.7),"Critical","At Risk")) -> At Risk
...

Sheet Operational_Data
A1: Rep_ID | B1: Region_ID | C1: Region_Name | D1: Month | E1: Working_Days | F1: Attendance_Days | G1: Attendance_Rate | H1: Planned_Visits | I1: Completed_Visits | J1: Visit_Completion_Rate | K1: Visit_Gap | L1: Merchandising_Compliance | M1: Merchandising_Target | N1: Merchandising_Gap | O1: Product_Availability | P1: Availability_Target | Q1: Availability_Gap | R1: Actual_Sales | S1: Target_Multiplier | T1: Target | U1: Sales_Achievement | V1: Sales_Gap | W1: Performance_Status
A2: 321500 | B2: 1 | C2: =INDEX(tblRegions[name],MATCH(B2,tblRegions[id],0)) -> Northeast | D2: 42005 | E2: 26 | F2: 23 | G2: =F2/E2 -> 0.88461538 | H2: 480 | I2: 413 | J2: =I2/H2 -> 0.86041667 | K2: =I2-H2 -> -67 | L2: 0.7299 | M2: 0.9 | N2: =L2-M2 -> -0.1701 | O2: 0.7952 | P2: 0.95 | Q2: =O2-P2 -> -0.1548 | R2: =SUMIFS(tblCleanOrders[Sales_USD],tblCleanOrders[Rep_ID],A2,tblCleanOrders[Year],YEAR(D2),tblCleanOrders[Month],MONTH(D2)) -> 1967.79 | S2: 1.05 | T2: =INDEX(tblRepAvg[Avg_Monthly_Sales],MATCH(A2,tblRepAvg[Rep_ID],0))*S2 -> 4580.3152 | U2: =IFERROR(R2/T2,0) -> 0.4296189 | V2: =R2-T2 -> -2612.5252 | W2: =IF(AND(U2>=0.9,L2>=0.8),"Healthy",IF(OR(U2<0.8,L2<0.7),"Critical","At Risk")) -> Critical
A3: 321500 | B3: 1 | C3: =INDEX(tblRegions[name],MATCH(B3,tblRegions[id],0)) -> Northeast | D3: 42036 | E3: 26 | F3: 22 | G3: =F3/E3 -> 0.84615385 | H3: 488 | I3: 395 | J3: =I3/H3 -> 0.80942623 | K3: =I3-H3 -> -93 | L3: 0.7713 | M3: 0.9 | N3: =L3-M3 -> -0.1287 | O3: 0.8649 | P3: 0.95 | Q3: =O3-P3 -> -0.0851 | R3: =SUMIFS(tblCleanOrders[Sales_USD],tblCleanOrders[Rep_ID],A3,tblCleanOrders[Year],YEAR(D3),tblCleanOrders[Month],MONTH(D3)) -> 1857.89 | S3: 1.06 | T3: =INDEX(tblRepAvg[Avg_Monthly_Sales],MATCH(A3,tblRepAvg[Rep_ID],0))*S3 -> 4623.9373 | U3: =IFERROR(R3/T3,0) -> 0.40179827 | V3: =R3-T3 -> -2766.0473 | W3: =IF(AND(U3>=0.9,L3>=0.8),"Healthy",IF(OR(U3<0.8,L3<0.7),"Critical","At Risk")) -> Critical
A4: 321500 | B4: 1 | C4: =INDEX(tblRegions[name],MATCH(B4,tblRegions[id],0)) -> Northeast | D4: 42064 | E4: 26 | F4: 22 | G4: =F4/E4 -> 0.84615385 | H4: 496 | I4: 433 | J4: =I4/H4 -> 0.87298387 | K4: =I4-H4 -> -63 | L4: 0.722 | M4: 0.9 | N4: =L4-M4 -> -0.178 | O4: 0.7934 | P4: 0.95 | Q4: =O4-P4 -> -0.1566 | R4: =SUMIFS(tblCleanOrders[Sales_USD],tblCleanOrders[Rep_ID],A4,tblCleanOrders[Year],YEAR(D4),tblCleanOrders[Month],MONTH(D4)) -> 1857.85 | S4: 1.07 | T4: =INDEX(tblRepAvg[Avg_Monthly_Sales],MATCH(A4,tblRepAvg[Rep_ID],0))*S4 -> 4667.5593 | U4: =IFERROR(R4/T4,0) -> 0.39803457 | V4: =R4-T4 -> -2809.7093 | W4: =IF(AND(U4>=0.9,L4>=0.8),"Healthy",IF(OR(U4<0.8,L4<0.7),"Critical","At Risk")) -> Critical
A5: 321500 | B5: 1 | C5: =INDEX(tblRegions[name],MATCH(B5,tblRegions[id],0)) -> Northeast | D5: 42095 | E5: 26 | F5: 23 | G5: =F5/E5 -> 0.88461538 | H5: 504 | I5: 433 | J5: =I5/H5 -> 0.85912698 | K5: =I5-H5 -> -71 | L5: 0.8058 | M5: 0.9 | N5: =L5-M5 -> -0.0942 | O5: 0.8455 | P5: 0.95 | Q5: =O5-P5 -> -0.1045 | R5: =SUMIFS(tblCleanOrders[Sales_USD],tblCleanOrders[Rep_ID],A5,tblCleanOrders[Year],YEAR(D5),tblCleanOrders[Month],MONTH(D5)) -> 1801.7 | S5: 1.08 | T5: =INDEX(tblRepAvg[Avg_Monthly_Sales],MATCH(A5,tblRepAvg[Rep_ID],0))*S5 -> 4711.1814 | U5: =IFERROR(R5/T5,0) -> 0.38243061 | V5: =R5-T5 -> -2909.4814 | W5: =IF(AND(U5>=0.9,L5>=0.8),"Healthy",IF(OR(U5<0.8,L5<0.7),"Critical","At Risk")) -> Critical
A6: 321500 | B6: 1 | C6: =INDEX(tblRegions[name],MATCH(B6,tblRegions[id],0)) -> Northeast | D6: 42125 | E6: 26 | F6: 22 | G6: =F6/E6 -> 0.84615385 | H6: 480 | I6: 392 | J6: =I6/H6 -> 0.81666667 | K6: =I6-H6 -> -88 | L6: 0.811 | M6: 0.9 | N6: =L6-M6 -> -0.089 | O6: 0.8118 | P6: 0.95 | Q6: =O6-P6 -> -0.1382 | R6: =SUMIFS(tblCleanOrders[Sales_USD],tblCleanOrders[Rep_ID],A6,tblCleanOrders[Year],YEAR(D6),tblCleanOrders[Month],MONTH(D6)) -> 2189.39 | S6: 1.09 | T6: =INDEX(tblRepAvg[Avg_Monthly_Sales],MATCH(A6,tblRepAvg[Rep_ID],0))*S6 -> 4754.8034 | U6: =IFERROR(R6/T6,0) -> 0.46045857 | V6: =R6-T6 -> -2565.4134 | W6: =IF(AND(U6>=0.9,L6>=0.8),"Healthy",IF(OR(U6<0.8,L6<0.7),"Critical","At Risk")) -> Critical
